# Debug Output Guide - Face Recognition

## What Was Fixed (Latest)

1. **Dlib Image Format**: Fixed PIL to numpy conversion to ensure uint8 type
2. **VGG16 Debug Logging**: Added comprehensive logging to see what's happening
3. **All Services**: Now show detailed step-by-step processing

## Your Current Situation

- **User**: `amenn` (ID: 6)
- **Encoding Type**: `vgg16_deep`
- **This means**: Your face was registered using the VGG16 deep learning model

## Expected Debug Output

When you try face login now, you should see:

### 1. Database Loading
```
üîç Starting face recognition...
üìä Found 1 registered face(s) in database
  üë§ User: amenn (ID: 6, encoding: vgg16_deep)
```

### 2. VGG16 Deep Learning Attempt
```
ü§ñ Trying Deep Learning (VGG16) recognition...
‚úì Loaded image successfully
  VGG16: Image loaded, shape: (height, width, 3)
  VGG16: Found 1 face(s)
  VGG16: Running model prediction...
  VGG16: Predicted class: X, confidence: 0.XXXX
  VGG16: Predicted name: 'SomeName'
  VGG16: Comparing with 1 stored encoding(s)...
  VGG16: Checking user 6, stored username: 'amenn'
```

**Two possible outcomes:**

#### ‚úÖ SUCCESS:
```
  VGG16: Match ACCEPTED - User 6 (confidence 0.XX >= 0.5)
‚úÖ Deep learning recognition SUCCESS: User 6, confidence 0.XX
üéâ Final result: Recognized as amenn
```

#### ‚ùå FAILURE - Wrong Name:
```
  VGG16: No matching username found for 'WrongName'
```
**Reason**: Model predicted a different person

#### ‚ùå FAILURE - Low Confidence:
```
  VGG16: Match REJECTED - Confidence 0.XX < 0.5
```
**Reason**: Not confident enough

### 3. Dlib Fallback (if VGG16 fails)
```
üîÑ Trying Dlib recognition (fallback)...
‚úì Dlib loaded image successfully (shape: (height, width, 3), dtype: uint8)
  Dlib: Detecting faces in image...
  Dlib: Found 1 face(s), computing encodings...
  Dlib: Comparing with 1 stored encoding(s)...
  Dlib: Skipping incompatible encoding for user 6
  Dlib: No compatible encodings found
```
**Note**: Dlib will skip because encoding is `vgg16_deep`, not `dlib`

## Common Issues & Solutions

### Issue 1: "No matching username found"

The VGG16 model was trained on specific users. Check what names it knows:
```python
.\venv\Scripts\python
>>> from ai_services.face_recognition_deep import deep_face_service
>>> deep_face_service._lazy_load()
>>> print(deep_face_service.label_encoder.classes_)
```

**Solution**: The model might have been trained with different usernames. You may need to:
- Re-register your face
- Or retrain the model with current users

### Issue 2: "Predicted class out of range"

Model output doesn't match label encoder.

**Solution**: Check model and encoder compatibility

### Issue 3: Low confidence

Model isn't sure it's you.

**Solution**: 
- Better lighting
- Face directly to camera
- Remove glasses/hat
- Re-register face

## Quick Test

1. Try face login
2. Copy the terminal output
3. Look for the key lines:
   - `Predicted name: 'XXX'`
   - `stored username: 'amenn'`
   
**If these match AND confidence >= 0.5**: Should work!
**If these don't match**: That's the problem!

## Next Steps Based on Output

### If predicted name ‚â† 'amenn'

The model thinks you're someone else. Check who the model was trained on:
```bash
.\venv\Scripts\python check_faces.py
```

Then look at the model training data in:
```
face-recognition-model/label_encoder.pkl
```

### If no faces detected

- Lighting issue
- Camera angle
- Try different browser/camera

### If everything looks correct but still fails

Check the username stored in the database encoding vs what the model expects.
